Workbook

Sheet DATA
B1: Each persona is one person you interview. Score every brand from 1 to 5 on each scale: 1 = the description on the left, 5 = the description on the right.
B2: persona | C2: 1
B3: 1 | C3: 5 | D3: Pizza Hut | E3: McDonald's | F3: Burger King | G3: KFC | H3: Dunkin' | I3: Starbucks | J3: Poke bowl
B4: Limited menu | C4: Menu with wide variety of combinations
B5: Few points of sale | C5: Many outlets
B6: Unhealthy food | C6: Very healthy food
B7: Conventional food | C7: Very entertaining/fun food
B8: Occasional meal | C8: Daily meal
B9: Low price | C9: High price
B10: Low total perceived value | C10: High total perceived value
B12: =B2 -> persona | C12: =C2+1 -> 2
B13: 1 | C13: 5 | D13: Pizza Hut | E13: McDonald's | F13: Burger King | G13: KFC | H13: Dunkin' | I13: Starbucks | J13: Poke bowl
B14: =B4 -> Limited menu | C14: =C4 -> Menu with wide variety of combinations
B15: =B5 -> Few points of sale | C15: =C5 -> Many outlets
B16: =B6 -> Unhealthy food | C16: =C6 -> Very healthy food
B17: =B7 -> Conventional food | C17: =C7 -> Very entertaining/fun food
B18: =B8 -> Occasional meal | C18: =C8 -> Daily meal
B19: =B9 -> Low price | C19: =C9 -> High price
B20: =B10 -> Low total perceived value | C20: =C10 -> High total perceived value
B22: =B12 -> persona | C22: =C12+1 -> 3
B23: 1 | C23: 5 | D23: Pizza Hut | E23: McDonald's | F23: Burger King | G23: KFC | H23: Dunkin' | I23: Starbucks | J23: Poke bowl
B24: =B14 -> Limited menu | C24: =C14 -> Menu with wide variety of combinations
B25: =B15 -> Few points of sale | C25: =C15 -> Many outlets
B26: =B16 -> Unhealthy food | C26: =C16 -> Very healthy food
B27: =B17 -> Conventional food | C27: =C17 -> Very entertaining/fun food
B28: =B18 -> Occasional meal | C28: =C18 -> Daily meal
B29: =B19 -> Low price | C29: =C19 -> High price
B30: =B20 -> Low total perceived value | C30: =C20 -> High total perceived value
B32: =B22 -> persona | C32: =C22+1 -> 4
B33: 1 | C33: 5 | D33: Pizza Hut | E33: McDonald's | F33: Burger King | G33: KFC | H33: Dunkin' | I33: Starbucks | J33: Poke bowl
B34: =B24 -> Limited menu | C34: =C24 -> Menu with wide variety of combinations
B35: =B25 -> Few points of sale | C35: =C25 -> Many outlets
B36: =B26 -> Unhealthy food | C36: =C26 -> Very healthy food
B37: =B27 -> Conventional food | C37: =C27 -> Very entertaining/fun food
B38: =B28 -> Occasional meal | C38: =C28 -> Daily meal
B39: =B29 -> Low price | C39: =C29 -> High price
B40: =B30 -> Low total perceived value | C40: =C30 -> High total perceived value
B42: =B32 -> persona | C42: =C32+1 -> 5
B43: 1 | C43: 5 | D43: Pizza Hut | E43: McDonald's | F43: Burger King | G43: KFC | H43: Dunkin' | I43: Starbucks | J43: Poke bowl
B44: =B34 -> Limited menu | C44: =C34 -> Menu with wide variety of combinations
...

Sheet data to import
B1: Pizza Hut | C1: McDonald's | D1: Burger King | E1: KFC | F1: Dunkin' | G1: Starbucks | H1: Poke bowl
A2: Menu variety | B2: =DATA!D64 | C2: =DATA!E64 | D2: =DATA!F64 | E2: =DATA!G64 | F2: =DATA!H64 | G2: =DATA!I64 | H2: =DATA!J64
A3: Number of outlets | B3: =DATA!D65 | C3: =DATA!E65 | D3: =DATA!F65 | E3: =DATA!G65 | F3: =DATA!H65 | G3: =DATA!I65 | H3: =DATA!J65
A4: Healthiness | B4: =DATA!D66 | C4: =DATA!E66 | D4: =DATA!F66 | E4: =DATA!G66 | F4: =DATA!H66 | G4: =DATA!I66 | H4: =DATA!J66
A5: Fun / entertainment | B5: =DATA!D67 | C5: =DATA!E67 | D5: =DATA!F67 | E5: =DATA!G67 | F5: =DATA!H67 | G5: =DATA!I67 | H5: =DATA!J67
A6: Occasional vs daily | B6: =DATA!D68 | C6: =DATA!E68 | D6: =DATA!F68 | E6: =DATA!G68 | F6: =DATA!H68 | G6: =DATA!I68 | H6: =DATA!J68
A7: Price level | B7: =DATA!D69 | C7: =DATA!E69 | D7: =DATA!F69 | E7: =DATA!G69 | F7: =DATA!H69 | G7: =DATA!I69 | H7: =DATA!J69
A8: Perceived value | B8: =DATA!D70 | C8: =DATA!E70 | D8: =DATA!F70 | E8: =DATA!G70 | F8: =DATA!H70 | G8: =DATA!I70 | H8: =DATA!J70
A10: Upload this workbook to the Positioning Maps tool as it is: the tool reads this sheet. No copying needed.
